<mujoco model="low_cost_robot">
  <compiler angle="radian" meshdir="assets"/>
  <asset>
    <mesh name="base_link" file="base_link.stl" scale="0.001 0.001 0.001"/>
    <mesh name="link1_1" file="link1_1.stl" scale="0.001 0.001 0.001"/>
    <mesh name="link2_1" file="link2_1.stl" scale="0.001 0.001 0.001"/>
    <mesh name="link3_1" file="link3_1.stl" scale="0.001 0.001 0.001"/>
    <mesh name="link4_1" file="link4_1.stl" scale="0.001 0.001 0.001"/>
    <mesh name="gripper_static_1" file="gripper_static_1.stl" scale="0.001 0.001 0.001"/>
    <mesh name="gripper_moving_1" file="gripper_moving_1.stl" scale="0.001 0.001 0.001"/>
  </asset>

  <default>
    <default class="position">
      <!-- <position ctrlrange="-6.2831 6.2831"/> -->
      <position ctrlrange="-6.2831 6.2831" kp="2000" kv="100" forcerange="-150 150"/>
      <default class="position_limited">
        <position ctrlrange="-3.1415 3.1415"/>
      </default>
      <!-- <default class="position_small">
        <position kp="500" kv="25" forcerange="-28 28"/>
      </default> -->
    </default>
  </default>

  <worldbody>
    <geom type="mesh" rgba="0.7 0.7 0.7 1" mesh="base_link"/>
    <body name="link1_1" pos="0 0 0.039">
      <inertial pos="-0.000621664 -0.0119142 0.0154002" quat="0.494768 0.505178 -0.505178 0.494768" mass="0.395606" diaginertia="0.000123021 0.000112 7.49792e-05"/>
      <joint name="joint1" pos="0 0 0" axis="0 0 1"/>
      <geom pos="0 0 -0.039" type="mesh" rgba="0.7 0.7 0.7 1" mesh="link1_1"/>
      <body name="link2_1" pos="-0.0002 0 0.0173">
        <inertial pos="0.000157789 -0.00121683 0.0716118" quat="0.689118 -0.0263852 0.0311302 0.723499" mass="0.391607" diaginertia="0.000537063 0.000519969 8.09683e-05"/>
        <joint name="joint2" pos="0 0 0" axis="-1 0 0"/>
        <geom pos="0.0002 0 -0.0563" type="mesh" rgba="0.7 0.7 0.7 1" mesh="link2_1"/>
        <body name="link3_1" pos="0.00025 0.014791 0.108347">
          <inertial pos="7.24367e-05 0.0506989 0.0028508" quat="0.501011 0.498987 -0.501011 0.498987" mass="0.440469" diaginertia="0.000322 0.000302004 5.4996e-05"/>
          <joint name="joint3" pos="0 0 0" axis="1 0 0"/>
          <geom pos="-5e-05 -0.014791 -0.164647" type="mesh" rgba="0.7 0.7 0.7 1" mesh="link3_1"/>
          <body name="link4_1" pos="0.000125 0.090467 0.002747">
            <inertial pos="-0.00473856 8.6083e-06 -0.0265782" quat="0.653281 0.270598 0.270598 0.653281" mass="0.154644" diaginertia="3.9e-05 2.7e-05 2.1e-05"/>
            <joint name="joint4" pos="0 0 0" axis="1 0 0"/>
            <geom pos="-0.000175 -0.105258 -0.167394" type="mesh" rgba="0.7 0.7 0.7 1" mesh="link4_1"/>
            <body name="gripper_static_1" pos="0.001353 7e-06 -0.045">
              <inertial pos="0.00544111 0.000115633 -0.0190522" quat="0.687452 -0.165558 -0.165558 0.687452" mass="0.230086" diaginertia="8.4e-05 7.82036e-05 3.37964e-05"/>
              <joint name="joint5" pos="0 0 0" axis="0 0 -1"/>
              <geom pos="-0.001528 -0.105265 -0.122394" type="mesh" rgba="0.7 0.7 0.7 1" mesh="gripper_static_1"/>
              <body name="gripper_moving_1" pos="-0.0074 -0.00025 -0.01315">
                <inertial pos="0.0010956 0.000310904 -0.0251131" quat="0.997878 0 -0.0651045 0" mass="0.100606" diaginertia="2.72621e-05 1.9e-05 1.17379e-05"/>
                <joint name="joint_gripper" pos="0 0 0" axis="0 -1 0"/>
                <geom pos="0.005872 -0.105015 -0.109244" type="mesh" rgba="0.7 0.7 0.7 1" mesh="gripper_moving_1"/>
              </body>
              <site name="tcp" size="0.001" pos="0.007 0 -0.068" quat="-1 1 1 1" rgba="1 0 0 1" group="1"/>
            </body>
          </body>
        </body>
      </body>
    </body>
  </worldbody>

  <actuator>
    <position class="position" name="joint1" joint="joint1"/>
    <position class="position_limited" name="joint2" joint="joint2"/>
    <position class="position_limited" name="joint3" joint="joint3"/>
    <position class="position_limited" name="joint4" joint="joint4"/>
    <position class="position_limited" name="joint5" joint="joint5"/>
    <!-- <position class="position" name="joint_gripper" joint="joint_gripper"/> -->
  </actuator>

  <keyframe>
    <key name="home" qpos="-1.5708 -1.5708 1.5708 -1.5708 -1.5708 0" ctrl="-1.5708 -1.5708 1.5708 -1.5708 -1.5708"/>
  </keyframe>
</mujoco>
